{
  "small_house": {
    "description": "A simple 3x3 spruce house with floor, walls, roof, and door opening",
    "origin": {"x": 0, "y": 0, "z": 0},
    "blocks": [
      {"x":-1,"y":0,"z":-1,"block":"spruce_planks"},
      {"x":0,"y":0,"z":-1,"block":"spruce_planks"},
      {"x":1,"y":0,"z":-1,"block":"spruce_planks"},
      {"x":-1,"y":0,"z":0,"block":"spruce_planks"},
      {"x":0,"y":0,"z":0,"block":"spruce_planks"},
      {"x":1,"y":0,"z":0,"block":"spruce_planks"},
      {"x":-1,"y":0,"z":1,"block":"spruce_planks"},
      {"x":0,"y":0,"z":1,"block":"spruce_planks"},
      {"x":1,"y":0,"z":1,"block":"spruce_planks"},
      {"x":-1,"y":1,"z":-1,"block":"spruce_log"},
      {"x":0,"y":1,"z":-1,"block":"spruce_planks"},
      {"x":1,"y":1,"z":-1,"block":"spruce_log"},
      {"x":-1,"y":1,"z":0,"block":"spruce_planks"},
      {"x":1,"y":1,"z":0,"block":"spruce_planks"},
      {"x":-1,"y":1,"z":1,"block":"spruce_log"},
      {"x":0,"y":1,"z":1,"block":"spruce_door"},
      {"x":1,"y":1,"z":1,"block":"spruce_log"},
      {"x":-1,"y":2,"z":-1,"block":"spruce_log"},
      {"x":0,"y":2,"z":-1,"block":"spruce_planks"},
      {"x":1,"y":2,"z":-1,"block":"spruce_log"},
      {"x":-1,"y":2,"z":0,"block":"spruce_planks"},
      {"x":1,"y":2,"z":0,"block":"spruce_planks"},
      {"x":-1,"y":2,"z":1,"block":"spruce_log"},
      {"x":0,"y":2,"z":1,"block":"spruce_door"},
      {"x":1,"y":2,"z":1,"block":"spruce_log"},
      {"x":-1,"y":3,"z":-1,"block":"spruce_planks"},
      {"x":0,"y":3,"z":-1,"block":"spruce_planks"},
      {"x":1,"y":3,"z":-1,"block":"spruce_planks"},
      {"x":-1,"y":3,"z":0,"block":"spruce_planks"},
      {"x":0,"y":3,"z":0,"block":"spruce_planks"},
      {"x":1,"y":3,"z":0,"block":"spruce_planks"},
      {"x":-1,"y":3,"z":1,"block":"spruce_planks"},
      {"x":0,"y":3,"z":1,"block":"spruce_planks"},
      {"x":1,"y":3,"z":1,"block":"spruce_planks"}
    ]
  },
  "medium_house": {
    "description": "A 5x5 spruce house with floor, walls, roof, and door opening",
    "origin": {"x": 0, "y": 0, "z": 0},
    "blocks": [
      {"x":-2,"y":0,"z":-2,"block":"spruce_planks"},
      {"x":-1,"y":0,"z":-2,"block":"spruce_planks"},
      {"x":0,"y":0,"z":-2,"block":"spruce_planks"},
      {"x":1,"y":0,"z":-2,"block":"spruce_planks"},
      {"x":2,"y":0,"z":-2,"block":"spruce_planks"},
      {"x":-2,"y":0,"z":-1,"block":"spruce_planks"},
      {"x":-1,"y":0,"z":-1,"block":"spruce_planks"},
      {"x":0,"y":0,"z":-1,"block":"spruce_planks"},
      {"x":1,"y":0,"z":-1,"block":"spruce_planks"},
      {"x":2,"y":0,"z":-1,"block":"spruce_planks"},
      {"x":-2,"y":0,"z":0,"block":"spruce_planks"},
      {"x":-1,"y":0,"z":0,"block":"spruce_planks"},
      {"x":0,"y":0,"z":0,"block":"spruce_planks"},
      {"x":1,"y":0,"z":0,"block":"spruce_planks"},
      {"x":2,"y":0,"z":0,"block":"spruce_planks"},
      {"x":-2,"y":0,"z":1,"block":"spruce_planks"},
      {"x":-1,"y":0,"z":1,"block":"spruce_planks"},
      {"x":0,"y":0,"z":1,"block":"spruce_planks"},
      {"x":1,"y":0,"z":1,"block":"spruce_planks"},
      {"x":2,"y":0,"z":1,"block":"spruce_planks"},
      {"x":-2,"y":0,"z":2,"block":"spruce_planks"},
      {"x":-1,"y":0,"z":2,"block":"spruce_planks"},
      {"x":0,"y":0,"z":2,"block":"spruce_planks"},
      {"x":1,"y":0,"z":2,"block":"spruce_planks"},
      {"x":2,"y":0,"z":2,"block":"spruce_planks"},
      {"x":-2,"y":1,"z":-2,"block":"spruce_log"},
      {"x":-1,"y":1,"z":-2,"block":"spruce_planks"},
      {"x":0,"y":1,"z":-2,"block":"spruce_planks"},
      {"x":1,"y":1,"z":-2,"block":"spruce_planks"},
      {"x":2,"y":1,"z":-2,"block":"spruce_log"},
      {"x":-2,"y":1,"z":-1,"block":"spruce_planks"},
      {"x":2,"y":1,"z":-1,"block":"spruce_planks"},
      {"x":-2,"y":1,"z":0,"block":"spruce_planks"},
      {"x":2,"y":1,"z":0,"block":"spruce_planks"},
      {"x":-2,"y":1,"z":1,"block":"spruce_planks"},
      {"x":2,"y":1,"z":1,"block":"spruce_planks"},
      {"x":-2,"y":1,"z":2,"block":"spruce_log"},
      {"x":-1,"y":1,"z":2,"block":"spruce_planks"},
      {"x":0,"y":1,"z":2,"block":"spruce_door"},
      {"x":1,"y":1,"z":2,"block":"spruce_planks"},
      {"x":2,"y":1,"z":2,"block":"spruce_log"},
      {"x":-2,"y":2,"z":-2,"block":"spruce_log"},
      {"x":-1,"y":2,"z":-2,"block":"spruce_planks"},
      {"x":0,"y":2,"z":-2,"block":"spruce_planks"},
      {"x":1,"y":2,"z":-2,"block":"spruce_planks"},
      {"x":2,"y":2,"z":-2,"block":"spruce_log"},
      {"x":-2,"y":2,"z":-1,"block":"spruce_planks"},
      {"x":2,"y":2,"z":-1,"block":"spruce_planks"},
      {"x":-2,"y":2,"z":0,"block":"spruce_planks"},
      {"x":2,"y":2,"z":0,"block":"spruce_planks"},
      {"x":-2,"y":2,"z":1,"block":"spruce_planks"},
      {"x":2,"y":2,"z":1,"block":"spruce_planks"},
      {"x":-2,"y":2,"z":2,"block":"spruce_log"},
      {"x":-1,"y":2,"z":2,"block":"spruce_planks"},
      {"x":0,"y":2,"z":2,"block":"spruce_door"},
      {"x":1,"y":2,"z":2,"block":"spruce_planks"},
      {"x":2,"y":2,"z":2,"block":"spruce_log"},
      {"x":-2,"y":3,"z":-2,"block":"spruce_planks"},
      {"x":-1,"y":3,"z":-2,"block":"spruce_planks"},
      {"x":0,"y":3,"z":-2,"block":"spruce_planks"},
      {"x":1,"y":3,"z":-2,"block":"spruce_planks"},
      {"x":2,"y":3,"z":-2,"block":"spruce_planks"},
      {"x":-2,"y":3,"z":-1,"block":"spruce_planks"},
      {"x":2,"y":3,"z":-1,"block":"spruce_planks"},
      {"x":-2,"y":3,"z":0,"block":"spruce_planks"},
      {"x":2,"y":3,"z":0,"block":"spruce_planks"},
      {"x":-2,"y":3,"z":1,"block":"spruce_planks"},
      {"x":2,"y":3,"z":1,"block":"spruce_planks"},
      {"x":-2,"y":3,"z":2,"block":"spruce_planks"},
      {"x":-1,"y":3,"z":2,"block":"spruce_planks"},
      {"x":0,"y":3,"z":2,"block":"spruce_planks"},
      {"x":1,"y":3,"z":2,"block":"spruce_planks"},
      {"x":2,"y":3,"z":2,"block":"spruce_planks"},
      {"x":-2,"y":4,"z":-2,"block":"spruce_planks"},
      {"x":-1,"y":4,"z":-2,"block":"spruce_planks"},
      {"x":0,"y":4,"z":-2,"block":"spruce_planks"},
      {"x":1,"y":4,"z":-2,"block":"spruce_planks"},
      {"x":2,"y":4,"z":-2,"block":"spruce_planks"},
      {"x":-2,"y":4,"z":-1,"block":"spruce_planks"},
      {"x":2,"y":4,"z":-1,"block":"spruce_planks"},
      {"x":-2,"y":4,"z":0,"block":"spruce_planks"},
      {"x":2,"y":4,"z":0,"block":"spruce_planks"},
      {"x":-2,"y":4,"z":1,"block":"spruce_planks"},
      {"x":2,"y":4,"z":1,"block":"spruce_planks"},
      {"x":-2,"y":4,"z":2,"block":"spruce_planks"},
      {"x":-1,"y":4,"z":2,"block":"spruce_planks"},
      {"x":0,"y":4,"z":2,"block":"spruce_planks"},
      {"x":1,"y":4,"z":2,"block":"spruce_planks"},
      {"x":2,"y":4,"z":2,"block":"spruce_planks"}
    ]
  }
}
